=== command
CI="true" GITHUB_ACTIONS="true" GITHUB_EVENT_NAME="pull_request" GITHUB_REPOSITORY="project_name/project_name" GITHUB_RUN_ID="35" GITHUB_ACTOR="some_test_username" GITHUB_REF="some/branch-name" GITHUB_SHA="<MASKED>" GITHUB_EVENT_PATH="<MASKED>" SEMGREP_APP_TOKEN="fake-key-from-tests" SEMGREP_USER_AGENT_APPEND="pytest" SEMGREP_SETTINGS_FILE="<MASKED>" SEMGREP_VERSION_CACHE_PATH="<MASKED>" SEMGREP_ENABLE_VERSION_CHECK="0" SEMGREP_SEND_METRICS="off" semgrep ci
=== end of command

=== exit code
2
=== end of exit code

=== stdout - plain

=== end of stdout - plain

=== stderr - plain
Scan environment:
  versions    - semgrep <MASKED> on python <MASKED>
  environment - running in environment github-actions, triggering event is pull_request
  semgrep.dev - authenticated as org_name

Command '['git', 'fetch', 'origin', '--depth', '1', '-fu', 'some/branch-name:some/branch-name']' returned non-zero exit status 128.
Traceback (most recent call last):
  File "/home/runner/work/semgrep/semgrep/semgrep/semgrep/commands/wrapper.py", line 35, in wrapper
    func(*args, **kwargs)
  File "/home/runner/work/semgrep/semgrep/semgrep/semgrep/commands/ci.py", line 306, in ci
    with fix_head_if_github_action(metadata):
  File "/usr/lib/python3.8/contextlib.py", line 113, in __enter__
    return next(self.gen)
  File "/home/runner/work/semgrep/semgrep/semgrep/semgrep/commands/ci.py", line 83, in fix_head_if_github_action
    assert metadata.head_branch_hash is not None  # Not none when github action PR
  File "/home/runner/.local/share/virtualenvs/semgrep-GqZ0EjEI/lib/python3.8/site-packages/boltons/cacheutils.py", line 641, in __get__
    value = obj.__dict__[self.func.__name__] = self.func(obj)
  File "/home/runner/work/semgrep/semgrep/semgrep/semgrep/meta.py", line 250, in head_branch_hash
    commit = self._get_latest_commit_hash_in_branch(head_branch_name)
  File "/home/runner/work/semgrep/semgrep/semgrep/semgrep/meta.py", line 218, in _get_latest_commit_hash_in_branch
    process = subprocess.run(
  File "/usr/lib/python3.8/subprocess.py", line 516, in run
    raise CalledProcessError(retcode, process.args,
subprocess.CalledProcessError: Command '['git', 'fetch', 'origin', '--depth', '1', '-fu', 'some/branch-name:some/branch-name']' returned non-zero exit status 128.

=== end of stderr - plain